Workbook

Sheet Instructions
A1: Diabetes Treatment Algorithm — Instructions
A2: Read this page before using the tool. Tabs are listed in the order you'll typically use them.
A4: Instructions for Patient Information Worksheet
A5: 1 | B5: Enter all patient parameters in the fields outlined in red (age, gender, weight, height, serum creatinine).
A6: 2 | B6: Select Yes/No for each Medical History item, including the new Obesity/overweight flag — these drive the preferred-therapy recommendations on the DM Medications tab.
A7: 3 | B7: Calculated values (Ideal/Adjusted Body Weight, BMI, CrCl, eGFR) populate automatically in blue — no need to enter these.
A9: Instructions for DM Medications Worksheet
A10: 1 | B10: Use the cardiorenal risk / comorbidity table to identify preferred therapy based on the history entered on the Patient Information tab (ASCVD, heart failure, CKD, obesity, MASLD/MASH).
A11: 2 | B11: Select an oral and/or injectable drug of choice from the red dropdown fields; dosing populates automatically in blue.
A12: 3 | B12: Reassess therapy, including the need for hypoglycemia-prone agents, every 3-6 months.
A14: Instructions for Insulin Worksheet
A15: 1 | B15: Use the initial dosing section to calculate starting insulin doses from patient weight (pulled automatically from Patient Information).
A16: 2 | B16: Use the Adjusting Insulin Regimen section to calculate correction dose and insulin-to-carb ratio from entered blood glucose values.
A17: 3 | B17: Use the Insulin Conversions section when switching between insulin products, including the new once-weekly insulin icodec (Awiqli) calculator.
A19: Instructions for SMBG Worksheet
A20: 1 | B20: Enter blood glucose readings in the red grid for each meal time (before/after breakfast, lunch, dinner, and bedtime).
A21: 2 | B21: Running averages, hypoglycemia count, and hyperglycemia count calculate automatically — hypoglycemic readings (<70) highlight red, readings over 180 highlight purple.
A22: 3 | B22: Reference current ADA blood sugar goals in the panel on the right, including the 2026 age/frailty-individualized and perioperative targets noted at the bottom of the tab.
A24: This tool is intended to support, not replace, clinical judgment. Verify all calculated values and dosing recommendations — especially any field marked new for ADA 2026 — before use in patient care.
A28: Created by | B28: Andrew Tran, PharmD, BCACP, BCPS
A29: Version | B29: 2.0 — updated to ADA Standards of Care in Diabetes—2026
A30: Created on | B30: 06/01/2019
A31: Last edit | B31: 08/03/2026

Sheet Patient Information
A1: Diabetes Treatment Algorithm — Patient Information
A2: Red = enter data here | Blue = calculated automatically | Green = updated for ADA Standards of Care in Diabetes—2026
A3: Disclaimer: use of this tool does not replace clinical judgment.
A4: Input Patient Parameters | F4: Conversions | G4: Enter | H4: Conversion
A5: Patient Age (years) | B5: 60 | F5: Enter lbs to convert to Kg | H5: =IF(G5="", "", G5/2.2)
A6: Gender (male, female) | B6: male | F6: Enter kg to convert to lbs | H6: =IF(G6="","", G6*2.2)
A7: Total Body Weight (kg) | B7: 60 | F7: Enter cm to inches | H7: =IF(G7="","", G7/2.54)
A8: Height (in) | B8: 65 | F8: Enter inches to cm | H8: =IF(G8="","", G8*2.54)
A9: Ideal Body Weight (kg) | B9: =IF(OR(B6="", B8=""), "", IF(B6="male", (50 + 2.3 * (B8 - 60)), IF(B6="female", (45.5 + 2.3 * (B8 - 60)), ""))) -> 61.5
A10: Adjusted Body Weight (kg) | B10: =IF(OR(B7="", B9=""), "", B9 + (0.4 * (B7 - B9))) -> 60.9
A11: Patient's BMI (%) | B11: =IF(OR(B7="", B8=""), "", B7 / (((B8*2.54) / 100) ^ 2)) -> 22.011878
A12: Weight used in CrCl calculation | B12: =IF(OR(B7="", B9=""), "", IF(B7<B9, "Actual Body Weight", IF(AND(B7>B9, B7<=(B9*1.3)), "Ideal Body Weight", IF(B7>(B9*1.3), "Adjusted Body Weight", "")))) -> Actual Body Weight
A13: Serum Creatinine (mg/L) | B13: 1.2
A14: CrCl via Cockcroft-Gault Equation (mL/min) | B14: =IF(OR(B5="", B6="", B7="", B9="", B10="", B13=""), "", IF(AND(B7<B9,B6="male"),((140-B5)*B7)/(B13*72),IF(AND(B7<B9,B6="female"),0.85*((140-B5)*B7)/(B13*72), IF(AND(B7<=(B9*1.3),B6="male"),((140-B5)*B9)/(B13*72),IF(AND(B7<=(B9*1.3),B6="female"),0.85*((140-B5)*B9)/(B13*72), IF(AND(B7>(B9*1.3),B6="male"),((140-B5)*B10)/(B13*72),IF(AND(B7>(B9*1.3),B6="female"),0.85*((140-B5)*B10)/(B13*72),""))))))) -> 55.555556
A15: EGFR (mL/min) | B15: =IF(OR(B13="", B6="", B5=""), "", 141 * MIN(B13 / IF(B6="male", 0.9, 0.7), 1) ^ IF(B6="male", -0.411, -0.329) * MAX(B13 / IF(B6="male", 0.9, 0.7), 1) ^ (-1.209) * 0.993 ^ B5) -> 65.331569
A18: Medical History (Yes/No — see DM Medications tab)
A19: ASCVD (established or high-risk)
A20: Heart Failure (preserved of reduced EF)
A21: Chronic Kidney Disease (eGFR < 60 mL/min and/or UAC > 30 mg/g)
A22: Obesity / overweight (BMI ≥ 27 kg/m² with comorbidity, or BMI ≥ 30 kg/m²)
A24: Source: American Diabetes Association. Standards of Care in Diabetes—2026. Diabetes Care. 2026;49(Suppl 1). Insulin dosing verified against FDA prescribing information (DailyMed), accessed Aug 2026.

Sheet DM Medications
A1: Type 2 Diabetes Pharmacotherapy | D1: ADA 2026 — Pharmacologic Approaches to Glycemic Treatment (Reference)
A2: Healthy lifestyle behaviors, self-management education/support, and social determinants of health should be considered in ALL patients. | D2: Reference only — summarized for quick lookup, not a substitute for the full ADA algorithm. This block is locked to protect it from accidental edits.
A3: First-line pharmacotherapy should be selected based upon patient-specific factors: glycemic management needs, cardiorenal risk, comorbidities, cost, and access. Consider combination pharmacotherapy at initiation if A1C is more than 1.5% above target goal. ADA 2026 update: in patients with established/high-risk ASCVD, heart failure, CKD, or obesity, consider an SGLT2 inhibitor and/or GLP-1 RA (or GIP/GLP-1 RA) at or near diagnosis — independent of metformin use or baseline A1C — rather than only as a later add-on. | B3: Consider early insulin initiation with extreme hyperglycemia: - Blood glucose > 300 mg/dL - A1C > 10% - Signs of catabolism
A4: Reassess and modify treatment every 3-6 months. | D4: Step | E4: Guidance
D5: 1. At diagnosis | E5: Initiate lifestyle modification + metformin (unless contraindicated) for all patients with T2DM, regardless of baseline A1C, alongside diabetes self-management education/support and screening for social determinants of health.
A6: Select Therapy Based on Cardiorenal Risk / Comorbidity | D6: 2. Compelling indication present?
A7: Comorbidity / Risk Factor | B7: Preferred Therapy | D7: ASCVD / high CV risk | E7: Add a GLP-1 RA or SGLT2i with proven CV benefit, independent of A1C or metformin use.
A8: ASCVD (established or high risk) | B8: GLP-1 RA or SGLT2i with proven CVD benefit. Consider initiating at or near diagnosis in high-risk patients, independent of metformin use (ADA 2026). | D8: Heart failure | E8: SGLT2i preferred (avoid TZDs); GLP-1 RA is a reasonable alternative.
A9: Heart Failure (HFrEF or HFpEF) | B9: SGLT2i with HF benefit preferred (avoid TZDs; avoid saxagliptin). GLP-1 RA with HF benefit, or GIP/GLP-1 RA (tirzepatide), also supported — particularly for HFpEF (ADA 2026, based on SUMMIT trial data; guideline-based, not an FDA cardiovascular-outcome label). | D9: CKD (eGFR <60 or albuminuria) | E9: SGLT2i with renal benefit preferred; add a GLP-1 RA if further glycemic or weight control is needed.
A10: Chronic Kidney Disease (eGFR < 60 mL/min and/or UACR > 30 mg/g) | B10: On maximally tolerated ACEi/ARB; SGLT2i with renal benefit. GLP-1 RA now also supported in T2DM with CKD (ADA 2026). Consider adding finerenone (nonsteroidal MRA) for persistent albuminuria (UACR ≥ 100 mg/g, eGFR 30-90) as a three-drug cardiorenal approach (ADA 2026). | D10: Obesity / weight is priority | E10: GLP-1 RA or GIP/GLP-1 RA (tirzepatide) — prioritize the agent with the greatest weight-loss efficacy the patient can access.
A11: Obesity / overweight (BMI ≥ 27 kg/m² with comorbidity, or BMI ≥ 30 kg/m²) | B11: GLP-1 RA or GIP/GLP-1 RA (tirzepatide) preferred — prioritize the agent with the greatest weight-loss efficacy the patient can access and tolerate (ADA 2026 expanded indication branch). | D11: Cost / access is major barrier | E11: Sulfonylurea or TZD is a reasonable add-on; weigh hypoglycemia and weight-gain trade-offs.
A12: MASLD / MASH (metabolic dysfunction-associated steatotic liver disease / steatohepatitis) | B12: GLP-1 RA or GIP/GLP-1 RA preferred. Pioglitazone also has evidence in MASH but weigh against weight-gain and heart-failure risk (ADA 2026 expanded indication branch). | D12: 3. No compelling indication | E12: Select based on efficacy, hypoglycemia risk, weight effect, cost, and patient preference through shared decision-making.
D13: 4. Not at A1C goal (~3 months) | E13: Intensify promptly — add a second agent from a different class; avoid therapeutic inertia. Consider early combination therapy at diagnosis for patients starting far from goal.
A14: New for ADA 2026: reassess the need for, and dose of, hypoglycemia-prone agents (sulfonylureas, meglitinides, insulin) whenever a new glucose-lowering medication is added, to reduce hypoglycemia risk and treatment burden. | D14: 5. Insulin need | E14: Initiate insulin at any point for severe hyperglycemia (BG >300 mg/dL, A1C >10%, or catabolic symptoms/ketosis), or when not at goal on maximal combination oral/injectable non-insulin therapy.
A15: ORALS | D15: Adapted from: American Diabetes Association. Standards of Care in Diabetes—2026. Diabetes Care. 2026;49(Suppl 1).
A16: Oral Drug of Choice? | B16: saxagliptin (Onglyza)
A17: Oral Drug Dosing | B17: =IF(B16="metformin","IR: start 500 mg PO daily or BID; ER: start 500 mg PO daily; titrate to 2000 mg daily (or 2550 daily with 850 mg TID)", IF(B16="glipizide","start 5 mg PO daily; doses above 15 mg should be divided BID; max 40 mg daily", IF(B16="glimepiride","Start 1-2 mg PO daily; max 8 mg daily", IF(B16="glyburide","Start 2.5-5 mg PO daily, max 20 mg daily", IF(B16="pioglitazone","Start 15-30 mg PO daily, max 45 mg daily", IF(B16="canagliflozin (Invokana)","Start 100 mg PO daily, max 300 mg daily", IF(B16="empagliflozin (Jardiance)","Start 10 mg PO daily; max 25 mg daily", IF(B16="dapagliflozin (Farxiga)","start 5 mg PO daily; max 10 mg daily", IF(B16="sitagliptin (Januvia)","100 mg PO daily; supplied as 25 mg, 50 mg, 100 mg", IF(B16="linagliptin (Tradjenta)","5 mg PO daily", IF(B16="saxagliptin (Onglyza)","2.5 mg or 5 mg PO daily", IF(B16="alogliptin (Nesina)","25 mg PO daily", IF(SEARCH("semaglutide",B16),"Start 3 mg PO daily x 30 days, then increase to 7 mg PO daily after 30 days; may be increased to 14 mg once daily (after 30 days)",""))))))))))))) -> 2.5 mg or 5 mg PO daily
A18: How Supplied | B18: =IF(B16="metformin","IR tablets: 500 mg, 850 mg, 1000 mg. ER tablets: 500 mg, 750 mg, 1000 mg.",IF(B16="glipizide","IR tablets: 5 mg, 10 mg. ER tablets: 2.5 mg, 5 mg, 10 mg.",IF(B16="glimepiride","Tablets: 1 mg, 2 mg, 4 mg.",IF(B16="glyburide","Tablets: 1.25 mg, 2.5 mg, 5 mg. Micronized tablets: 0.75 mg, 1.5 mg, 3 mg, 6 mg.",IF(B16="pioglitazone","Tablets: 15 mg, 30 mg, 45 mg.",IF(B16="canagliflozin (Invokana)","Tablets: 100 mg, 300 mg.",IF(B16="empagliflozin (Jardiance)","Tablets: 10 mg, 25 mg.",IF(B16="dapagliflozin (Farxiga)","Tablets: 5 mg, 10 mg.",IF(B16="sitagliptin (Januvia)","Tablets: 25 mg, 50 mg, 100 mg.",IF(B16="linagliptin (Tradjenta)","Tablets: 5 mg (single strength).",IF(B16="saxagliptin (Onglyza)","Tablets: 2.5 mg, 5 mg.",IF(B16="alogliptin (Nesina)","Tablets: 6.25 mg, 12.5 mg, 25 mg.",IF(SEARCH("semaglutide",B16),"Tablets: 3 mg, 7 mg, 14 mg.",""))))))))))))) -> Tablets: 2.5 mg, 5 mg.
A19: Renal Dosing | B19: =IF(B16="metformin","eGFR ≥45: no adjustment. eGFR 30-45: do not initiate; if already on therapy, reassess risk/benefit and consider max 1000 mg/day. eGFR <30: contraindicated.",IF(B16="glipizide","No FDA eGFR table. Renal impairment: reduce starting dose and titrate conservatively — increased hypoglycemia risk from accumulation of active metabolites.",IF(B16="glimepiride","No hard eGFR cutoff. Start 1 mg daily (not the usual 1-2 mg) in renal impairment; titrate conservatively. Max 8 mg/day.",IF(B16="glyburide","No FDA eGFR table. Significant renal excretion — use conservative dosing in renal impairment (increased hypoglycemia risk); commonly avoided in significant CKD.",IF(B16="pioglitazone","No dose adjustment needed at any level of renal impairment (primarily hepatic/biliary elimination).",IF(B16="canagliflozin (Invokana)","eGFR ≥60: start 100 mg, may increase to 300 mg. eGFR 45-<60: max 100 mg. Do not initiate if eGFR <45. Contraindicated if eGFR <30.",IF(B16="empagliflozin (Jardiance)","Glycemic use: do not initiate if eGFR <45; ineffective if eGFR <30. CKD/HF indications: may initiate down to eGFR 20 and continue below. Contraindicated on dialysis.",IF(B16="dapagliflozin (Farxiga)","eGFR ≥45: standard dosing. eGFR 25-<45: 10 mg daily (all indications). eGFR <25: do not initiate; may continue 10 mg daily if already established for CKD/HF/CV risk reduction.",IF(B16="sitagliptin (Januvia)","eGFR ≥45: 100 mg daily. eGFR 30-<45: 50 mg daily. eGFR <30 (incl. dialysis): 25 mg daily, without regard to dialysis timing.",IF(B16="linagliptin (Tradjenta)","No dose adjustment at any level of renal impairment, including ESRD.",IF(B16="saxagliptin (Onglyza)","eGFR ≥45: no adjustment. eGFR <45 (incl. ESRD/dialysis): reduce to 2.5 mg daily; give after hemodialysis session.",IF(B16="alogliptin (Nesina)","CrCl ≥60: 25 mg daily. CrCl 30-<60: 12.5 mg daily. CrCl 15-<30 or ESRD/dialysis: 6.25 mg daily, without regard to dialysis timing.",IF(SEARCH("semaglutide",B16),"No dose adjustment required at any level of renal impairment, including ESRD.",""))))))))))))) -> eGFR ≥45: no adjustment. eGFR <45 (incl. ESRD/dialysis): reduce to 2.5 mg daily; give after hemodialysis session.
A21: INJECTABLES
A22: Injectable Drug of Choice? | B22: dulaglutide (Trulicity)
A23: Injectable Drug Dosing | B23: =IF(B22="liraglutide (Victoza)","Start 0.6 mg SQ once daily x1 week (not for glycemic control); increase to 1.2 mg once daily; may increase to max 1.8 mg once daily if needed",IF(B22="dulaglutide (Trulicity)","Start 0.75 mg SQ once weekly; may increase to 1.5 mg weekly after at least 4 weeks; if additional control needed, may increase to 3 mg weekly, then 4.5 mg weekly (each after at least 4 weeks on prior dose); max 4.5 mg weekly",IF(B22="exenatide (Byetta)","Start 5 mcg SQ twice daily within 60 minutes before morning and evening meals; after 1 month, may increase to 10 mcg SQ twice daily",IF(B22="exenatide ER (Bydureon)","2 mg SQ once weekly, any time of day, with or without meals",IF(B22="semaglutide (Ozempic)","Start 0.25 mg SQ once weekly x4 weeks (not for glycemic control); increase to 0.5 mg weekly; may increase to 1 mg weekly after at least 4 weeks; if additional control needed, may increase to max 2 mg weekly after at least 4 weeks on 1 mg",IF(B22="tirzepatide (Mounjaro)","Start 2.5 mg SQ once weekly x4 weeks (not for glycemic control); increase to 5 mg weekly; may increase in 2.5 mg increments after at least 4 weeks on current dose; max 15 mg weekly",IF(B22="pramlintide (SymlinPen)","Adjunct to mealtime insulin: start 60 mcg SQ immediately before major meals; may increase to 120 mcg as tolerated. Reduce prandial insulin doses by 50% when initiating to reduce hypoglycemia risk.",""))))))) -> Start 0.75 mg SQ once weekly; may increase to 1.5 mg weekly after at least 4 weeks; if additional control needed, may increase to 3 mg weekly, then 4.5 mg weekly (each after at least 4 weeks on prior dose); max 4.5 mg weekly
A24: How Supplied | B24: =IF(B22="liraglutide (Victoza)","Prefilled multi-dose pen, 18 mg/3 mL (6 mg/mL); dial doses of 0.6 mg, 1.2 mg, 1.8 mg.",IF(B22="dulaglutide (Trulicity)","Single-dose prefilled pens/syringes, 0.5 mL each: 0.75 mg, 1.5 mg, 3 mg, 4.5 mg.",IF(B22="exenatide (Byetta)","Prefilled multi-dose pens: 5 mcg/dose and 10 mcg/dose (60 doses each).",IF(B22="exenatide ER (Bydureon)","Single-dose tray/pen or BCise autoinjector, 2 mg per weekly dose.",IF(B22="semaglutide (Ozempic)","Prefilled pens: 2 mg/3 mL (0.25/0.5 mg doses), 4 mg/3 mL (1 mg doses), 8 mg/3 mL (2 mg doses).",IF(B22="tirzepatide (Mounjaro)","Single-dose pens/vials, 0.5 mL each: 2.5, 5, 7.5, 10, 12.5, 15 mg.",IF(B22="pramlintide (SymlinPen)","SymlinPen60: 15/30/45/60 mcg doses. SymlinPen120: 60/120 mcg doses.",""))))))) -> Single-dose prefilled pens/syringes, 0.5 mL each: 0.75 mg, 1.5 mg, 3 mg, 4.5 mg.
A25: Renal Dosing | B25: =IF(B22="liraglutide (Victoza)","No adjustment for mild-moderate renal impairment. Not recommended in ESRD (limited clinical experience).",IF(B22="dulaglutide (Trulicity)","No dose adjustment required across renal impairment stages, including ESRD/dialysis (limited data in ESRD).",IF(B22="exenatide (Byetta)","CrCl 50-80: no adjustment. CrCl 30-50: use caution when initiating or escalating dose. CrCl <30 or ESRD: not recommended.",IF(B22="exenatide ER (Bydureon)","Not recommended if eGFR <45 or ESRD. Use caution in mild impairment.",IF(B22="semaglutide (Ozempic)","No dose adjustment necessary for any degree of renal impairment, including ESRD.",IF(B22="tirzepatide (Mounjaro)","No dose adjustment necessary for any degree of renal impairment, including ESRD.",IF(B22="pramlintide (SymlinPen)","No adjustment for mild-severe renal impairment (CrCl ≥15). Not studied in ESRD — no dosing guidance available.",""))))))) -> No dose adjustment required across renal impairment stages, including ESRD/dialysis (limited data in ESRD).
A27: FIRST-LINE THERAPY: METFORMIN
A28: Dosage | B28: - Initial, 500 mg orally twice daily OR 850 mg orally once daily with meals; may adjust dose in 500 mg increments weekly OR 850 mg every 2 weeks; if desired, patients initiated at 500 mg twice daily may be switched to 850 mg twice daily after 2 weeks; MAX dose, 2550 mg/day; max effective dose: 2000 mg daily. Doses greater than 2000 mg/day may be better tolerated if given in 3 divided doses - Renal impairment, eGFR below 30 mL/min/1.73 m(2): Use is contraindicated - Renal impairment, eGFR between 30 to 45 mL/min/1.73 m(2): Use not recommended - Renal impairment, eGFR falls below 45 mL/min/1.73 m(2) after initiation: Assess benefits and risks of continuing treatment - Renal impairment, eGFR falls below 30 mL/min/1.73 m(2) after initiation: Discontinue treatment
A30: Recommended as foundational therapy independent of baseline A1C or A1C target (ADA 2026 — unchanged).
A32: DRUG CLASS REFERENCE
A33: SGLT-2 Inhibitors
A34: CVD Benefit (FDA approved) | B34: - canagliflozin (Invokana) - empagliflozin (Jardiance)
A35: HF Benefit (FDA approved) | B35: - dapagliflozin (Farxiga) - empagliflozin (Jardiance)
A36: Renal benefit (FDA approved) | B36: - canagliflozin (Invokana) - dapagliflozin (Farxiga) - empagliflozin (Jardiance)
A37: Dosing | B37: - canagliflozin (Invokana) - Start 100 mg PO daily; max 300 mg daily - dapagliflozin (Farxiga) - Start 5 mg PO daily; max 10 mg daily - empagliflozin (Jardiance) - Start 10 mg PO daily; max 25 mg daily
A38: eGFR cutoffs (glycemic indication) | B38: - canagliflozin (Invokana): eGFR 30-50: max dose 100 mg once daily; eGFR <30 or HD: Not recommended - dapagliflozin (Farxiga): eGFR < 60: Contraindicated - empagliflozin (Jardiance): eGFR < 45: Contraindicated
A39: Cardiorenal combination (ADA 2026) | B39: In T2DM with albuminuria (UACR ≥ 100 mg/g) and eGFR 30-90, consider combining an SGLT2i + finerenone (nonsteroidal MRA) + maximally tolerated ACEi/ARB for cardiorenal risk reduction.
A40: GLP-1 RAs / GIP-GLP-1 RA
A41: CVD Benefit (FDA approved) | B41: - dulaglutide (Trulicity) - liraglutide (Victoza) - semaglutide (Ozempic; Rybelsus)
A42: HF Benefit | B42: Neutral by FDA CV-outcome labeling for dulaglutide/liraglutide/semaglutide. GIP/GLP-1 RA (tirzepatide) shows benefit in HFpEF per the SUMMIT trial and is supported for HFpEF per ADA 2026 Standards of Care — this is guideline-based, not an FDA cardiovascular-outcome label.
A43: Renal Benefit | B43: Not FDA-approved as a dedicated renal-outcome indication for this class. ADA 2026 now supports GLP-1 RA / GIP-GLP-1 RA use in T2DM with CKD as part of individualized cardiorenal care.
A44: Dosing | B44: - dulaglutide (Trulicity) - Start 0.75 mg SQ once weekly; max to 1.5 mg SQ weekly - liraglutide (Victoza) - Start 0.6 mg SQ once daily for 1 week, then increase 1.2 mg once daily; then may increase to 1.8 mg daily - semaglutide (Ozempic) - Start 0.25 mg SQ once weekly for 4 weeks, then increase to 0.5 mg once weekly; may increase to 1 mg once weekly. If additional glycemic control needed after at least 4 weeks on 1 mg dosage, may increase to MAX of 2 mg once weekly - semaglutide (Rybelsus) - Start 3 mg orally daily for 30 days, then increase dose to 7 mg once daily, dose may be increased to 14 mg once daily after at least 30 days on 7 mg.
...

Sheet Insulin 
A1: Diabetes Treatment Algorithm — Insulin Dosing | F1: Insulin Calculations — Spelled Out (Reference)
A2: Select or Evaluate Initial Insulin Dose | Red = enter data | Blue = calculated | Green = new for ADA 2026 | F2: Every formula this tool uses, written out in full. Locked to protect it from accidental edits.
A3: Disclaimer: use of this tool does not replace clinical judgment.
F4: Calculation | G4: Formula / Logic
A5: Select Insulin Dosing Regimen — Initial | F5: Total Daily Dose (TDD) estimate | G5: 0.4-1.0 units/kg/day. Use the lower end for insulin-sensitive patients (T1DM, renal impairment, elderly); use the higher end for insulin resistance.
A6: Initiating Insulin in Type 1 Diabetes | F6: Basal-bolus, 50/50 split | G6: Basal (long-acting) = 50% of TDD. Bolus (rapid-acting) = 50% of TDD, divided across meals.
A7: Insulin TDD | B7: 0.4-1.0 units/kg/day | F7: Basal-bolus, NPH + Regular (2/3, 1/3) | G7: NPH = 2/3 of TDD. Regular = 1/3 of TDD.
B8: =CONCATENATE(('Patient Information'!B7*0.4)," - ",('Patient Information'!B7*1)," units q daily") -> 24 - 60 units q daily | F8: 70/30 mix regimen | G8: Total dose = 0.5 units/kg/day, given as 2/3 in the AM and 1/3 in the PM.
A9: Basal-Bolus Strategy | F9: T2DM basal starting dose | G9: 10 units/day, OR 0.1-0.2 units/kg/day.
A10: If using Long-Acting + Rapid-Acting insulin (50/50) | B10: =IF(OR(ISBLANK('Patient Information'!B7)), "", CONCATENATE(ROUND(0.5 * ('Patient Information'!B7 * 0.4), 0), " - ", ROUND((0.5 * 'Patient Information'!B7 * 1), 0), " units of basal q daily")) -> 12 - 30 units of basal q daily | C10: PLUS | D10: =IF(ISBLANK('Patient Information'!B7), "", CONCATENATE(ROUND((0.5 * ('Patient Information'!B7 * 0.4)) / 3, 0), " - ", ROUND(((0.5 * 'Patient Information'!B7 * 1) / 3), 0), " units of bolus TID with meals")) -> 4 - 10 units of bolus TID with meals | F10: Adding bolus insulin (T2DM, not at goal) | G10: 4 units/day, OR 10% of TDD, given with the largest meal.
A11: If using NPH and regular insulin (2/3 , 1/3) | B11: =IF(ISBLANK('Patient Information'!B7), "", CONCATENATE(ROUND(0.667 * ('Patient Information'!B7 * 0.4), 0), " - ", ROUND(0.667 * ('Patient Information'!B7 * 1), 0), " units of NPH BID")) -> 16 - 40 units of NPH BID | C11: PLUS | D11: =IF(ISBLANK('Patient Information'!B7), "", CONCATENATE(ROUND(0.334 * ('Patient Information'!B7 * 0.4), 0), " - ", ROUND(0.334 * ('Patient Information'!B7 * 1), 0), " units of regular BID with meals")) -> 8 - 20 units of regular BID with meals | F11: Insulin sensitivity factor (ISF / correction factor) | G11: Rapid-acting — Rule of 1800: 1800 / TDD = mg/dL lowered per 1 unit. Regular — Rule of 1500: 1500 / TDD = mg/dL lowered per 1 unit.
A12: if using insulin 70/30 (0.5 units/kg/day -- > 2/3 AM + 1/3 PM) | B12: =IF(ISBLANK('Patient Information'!B7), "", CONCATENATE(ROUND(('Patient Information'!B7 * 0.5) * 0.667, 0), " units of 70/30 AM + ", ROUND(('Patient Information'!B7 * 0.5) * 0.334, 0), " units of 70/30 PM with meals")) -> 20 units of 70/30 AM + 10 units of 70/30 PM with meals | F12: Insulin-to-carb ratio (ICR) | G12: Rapid-acting — Rule of 500: 500 / TDD = grams of carb covered per 1 unit. Regular — Rule of 450: 450 / TDD = grams of carb covered per 1 unit.
A13: Initiating Insulin in Type 2 Diabetes | F13: Correction dose | G13: (Current BG − Target BG) ÷ ISF (correction factor) = units of correction insulin.
A14: Basal Insulin Dose | B14: Basal Insulin is initated at 10 units daily OR 0.1-0.2 units/kg/day | F14: Insulin icodec (Awiqli), Week 1 dose | G14: ROUND(1.5 × 7-day total basal dose ÷ 10, 0) × 10 — a one-time starting dose, rounded to the nearest 10 units.
B15: 10 units q daily | C15: OR | D15: =IF(ISBLANK('Patient Information'!B7), "", CONCATENATE(('Patient Information'!B7*0.1)," - ",('Patient Information'!B7*0.2)," units q daily")) -> 6 - 12 units q daily | F15: Insulin icodec (Awiqli), Week 2 onward | G15: ROUND(7-day total basal dose ÷ 10, 0) × 10 units — rounded to the nearest 10 units.
A17: Adjusting Insulin Regimen | F17: Insulin Conversion Reference
A18: Enter TDD of insulin | F18: General starting-point conversion principles — always individualize and monitor closely after any insulin switch. Locked to protect it from accidental edits.
A19: Adding bolus insulin in T2DM | B19: If not at goal, bolus insulin is initiated at 4 units/day OR 10% of TDD | F19: Switching from / to | G19: Conversion
B20: 4 units per day with largest meal | C20: OR | D20: =IF(ISBLANK(B18), "", CONCATENATE(ROUND(B18*0.1, 0), " units per day with largest meal")) | F20: NPH once daily → glargine or detemir U-100 | G20: Convert unit-for-unit; give once daily.
A21: Enter rapid or regular Insulin as bolus? | F21: NPH twice daily → glargine U-100 once daily | G21: Reduce total daily dose by 20%; give once daily.
A22: Insulin sensitivity factor (rule of 1800 or 1500) | B22: =IF(OR(ISBLANK(B21),ISBLANK(B18)),"",IF(B21="rapid",CONCATENATE(ROUND(1800/B18,0)," mg/dL lowered by 1 unit of rapid"),IF(B21="regular",CONCATENATE(ROUND(1500/B18,0)," mg/dL of glucose lowered by 1 unit of regular"),""))) | F22: Once-daily basal (glargine U-100, detemir, or NPH) → glargine U-300 (Toujeo) | G22: Same unit dose (1:1).
A23: Insulin-to-carb ratio (rule of 500 or 450) | B23: =IF(OR(ISBLANK(B21), ISBLANK(B18)), "", IF(B21="rapid", CONCATENATE(ROUND(500/B18, 0), " grams of carb covered by 1 unit of rapid"), IF(B21="regular", CONCATENATE(ROUND(450/B18, 0), " grams of carb covered by 1 unit of regular"), ""))) | F23: Twice-daily long/intermediate-acting (e.g., detemir, NPH) → glargine U-300 (Toujeo) | G23: Initiate at 80% of the total daily twice-daily dose.
A24: Correction Dose | B24: [Current BG - Target BG]/Correction Factor | F24: Any basal analog → degludec (Tresiba) | G24: Convert unit-for-unit; a higher dose of the ultra-long-acting agent may be needed for equivalent effect — titrate to response.
A25: Enter current BG | F25: Regular → rapid-acting (lispro, aspart, glulisine) | G25: Convert unit-for-unit as a starting point.
A26: Enter target BG | F26: U-100 / U-200 / U-300 basal → U-500 regular | G26: A1C >8%: same total daily dose. A1C ≤8%: reduce total daily dose by 20%.
A27: Calculated Correction Dose | B27: =IF(OR(ISBLANK(B21), ISBLANK(B25), ISBLANK(B26), ISBLANK(B18)), "", IF(B21="rapid", ROUND((B25-B26)/(1800/B18), 0) & " units of rapid insulin", IF(B21="regular", ROUND((B25-B26)/(1500/B18), 0) & " units of regular insulin", ""))) | F27: General mixed-insulin (70/30, 75/25, 50/50) switches | G27: Convert unit-for-unit when the mix ratio is similar; reassess the AM/PM split if the ratio changes.
F28: Sources: institutional insulin conversion practice; Cardi-OH Guide to Therapeutic Interchange of Insulin Products (Nov 2025); product prescribing information for glargine U-300 (Toujeo) and U-500 regular.
A29: Insulin Conversions
A30: Basal insulin conversions
A31: Enter current basal insulin
A32: Enter current insulin dose
A33: Enter desired basal insulin
A34: Calculated desired insulin dose (TDD) | B34: =IF(OR(ISBLANK(B31), ISBLANK(B32), ISBLANK(B33)), "", IF(AND(B31="NPH BID", NOT(OR(B33="NPH BID", B33="Insulin degludec (Tresiba)", B33="Insulin detemir (Levemir)"))), B32*0.8, IF(AND(NOT(OR(B31="NPH BID", B31="Insulin detemir (Levemir)", B31="Insulin degludec (Tresiba)")), OR(B33="NPH BID", B33="Insulin detemir (Levemir)", B33="Insulin degludec (Tresiba)")), B32/0.8, IF(AND(B31="Insulin glargine (Toujeo)", NOT(OR(B33="Insulin glargine (Toujeo)", B33="Insulin degludec (Tresiba)"))), B32*0.8, IF(AND(NOT(OR(B31="Insulin glargine (Toujeo)", B31="Insulin degludec (Tresiba)")), OR(B33="Insulin glargine (Toujeo)", B33="Insulin degludec (Tresiba)")), B32/0.8, IF(AND(OR(B31="Regular (R)", B31="Novolin"), NOT(OR(B33="Regular (R)", B33="Novolin", B33="Regular (R) or Novolin"))), B32*0.8, IF(AND(NOT(OR(B31="Regular (R)", B31="Novolin")), OR(B33="Regular (R)", B33="Novolin", B33="Regular (R) or Novolin")), B32/0.8, B32) ) ) ) ) ) )
A35: Bolus insulin conversions
A36: Enter current bolus insulin
A37: Enter current insulin dose
A38: Enter desired bolus insulin
A39: Calculated desired insulin dose | B39: =IF(OR(ISBLANK(B36), ISBLANK(B37), ISBLANK(B38)), "", IF(AND(B36="Regular (R)", OR(B38="Insulin aspart (Novolog)", B38="Insulin lispro (Humalog)", B38="Insulin glulisine (Apidra)")), B37*0.8, IF(AND(OR(B36="Insulin aspart (Novolog)", B36="Insulin lispro (Humalog)", B36="Insulin glulisine (Apidra)"), B38="Regular (R)"), B37/0.8, B37) ) )
A40: Mixed insulin conversions
A41: Enter current mixed insulin
...

Sheet SMBG
A1: Diabetes Treatment Algorithm — SMBG Averages
A2: SMBG Averages | Red = enter data | Blue = calculated | Green = new for ADA 2026
A3: Disclaimer: use of this tool does not replace clinical judgment.
B4: Enter SMBG values | H4: Running average | K4: ADA Blood Sugar Goals
A5: Before Breakfast | H5: =IF(COUNT(B5:G9) > 0, ROUND(AVERAGE(B5:G9), 1), "") | K5: A1c | L5: <7%
K6: Fasting | L6: 80-130
K7: 2 hours post-prandial | L7: < 180
K8: Hypoglycemia | L8: <70
A10: After Breakfast | H10: =IF(COUNT(B10:G14) > 0, ROUND(AVERAGE(B10:G14), 1), "") | K10: Hypoglycemic SMBG < 70 will change cell red
K11: SMBG > 180 will change cell purple
K13: Overall Average | L13: =IF(COUNT(H5:H39) > 0, ROUND(AVERAGE(H5:H39), 1), "")
K14: # Hypoglycemic SMBG | L14: =COUNTIF(B5:G39,"<70") -> 0
A15: Before Lunch | H15: =IF(COUNT(B15:G19) > 0, ROUND(AVERAGE(B15:G19), 1), "") | K15: # SMBG > 180 | L15: =COUNTIF(B5:G39, ">180") -> 0
K17: Conversions | L17: Enter | M17: Conversion
K18: A1C to estimated glucose | M18: =IF(L18="", "", 28.7*L18-46.7)
K19: Average glucose to A1c | M19: =IF(L19="", "", ((L19+46.7)/28.7))
A20: After Lunch | H20: =IF(COUNT(B20:G24) > 0, ROUND(AVERAGE(B20:G24), 1), "")
A25: Before Dinner | H25: =IF(COUNT(B25:G29) > 0, ROUND(AVERAGE(B25:G29), 1), "")
A30: After Dinner | H30: =IF(COUNT(B30:G34) > 0, ROUND(AVERAGE(B30:G34), 1), "")
A35: Bedtime | H35: =IF(COUNT(B35:G39) > 0, ROUND(AVERAGE(B35:G39), 1), "")
A41: ADDITIONAL 2026 ADA TARGETS — new
A42: Glycemic and CGM targets are now framed more explicitly around age, frailty, and functional/health status rather than a single flat number — individualize the <7% A1C goal accordingly, especially in older adults (ADA 2026, Sections 6 and 13).
A43: New perioperative target (ADA 2026): A1C ≤ 8% before elective surgery; inpatient glucose 100-180 mg/dL before, during, and after surgery.
A45: Source: American Diabetes Association. Standards of Care in Diabetes—2026. Diabetes Care. 2026;49(Suppl 1), Sections 6 and 13. Core fasting/postprandial/hypoglycemia numeric thresholds (80-130, <180, <70 mg/dL) verified as carryover with no confirmed 2026 numeric change; cross-check Table 6.2 directly if this tool is used for a non-standard target population.
